<?xml version="1.0" ?>
<mujoco model="square_pull">
    <option timestep="0.005" />
    <asset>
        <texture type="2d" name="texplane" builtin="checker" rgb1="0.2 0.3 0.4" rgb2="0.1 0.2 0.3" width="512" height="512" mark="cross" />
        <material name="mplane" texture="texplane" />
    </asset>
    <worldbody>
        <geom type="plane" size="1 1 0.1" material="mplane" />
        <body name="square" pos="0 0 0.05">
            <geom type="box" size="0.1 0.1 0.1" rgba="1 0 0 1" />
        </body>
        <body name="rod1" pos="-0.5 0 0">
            <joint type="slide" axis="1 0 0"/>
            <geom type="capsule" fromto="0 0 0 0.5 0 0" size="0.05" rgba="0 1 0 1"/>
        </body>
        <body name="rod2" pos="0 0.5 0">
            <joint type="slide" axis="0 1 0"/>
            <geom type="capsule" fromto="0 0 0 0 0.5 0" size="0.05" rgba="0 1 0 1"/>
        </body>
    </worldbody>
</mujoco>
